Workbook

Sheet Stock Prices
A1: worksheet for estimating σ
B2: historic prices
A3: j | B3: Sj | C3: Rj = Sj/Sj-1 | D3: log Rj | E3: log Rj - µ | F3: (log Rj - µ)²
A4: 1 | B4: 6929.94
A5: 2 | B5: 6858.47 | C5: =B5/B4 | D5: =LN(C5) | E5: =D5-$B$37 | F5: =E5^2
A6: 3 | B6: 6966.28 | C6: =B6/B5 | D6: =LN(C6) | E6: =D6-$B$37 | F6: =E6^2
A7: 4 | B7: 6940.01 | C7: =B7/B6 | D7: =LN(C7) | E7: =D7-$B$37 | F7: =E7^2
A8: 5 | B8: 6915.61 | C8: =B8/B7 | D8: =LN(C8) | E8: =D8-$B$37 | F8: =E8^2
A9: 6 | B9: 6939.03 | C9: =B9/B8 | D9: =LN(C9) | E9: =D9-$B$37 | F9: =E9^2
A10: 7 | B10: 6932.3 | C10: =B10/B9 | D10: =LN(C10) | E10: =D10-$B$37 | F10: =E10^2
A11: 8 | B11: 6836.17 | C11: =B11/B10 | D11: =LN(C11) | E11: =D11-$B$37 | F11: =E11^2
A12: 9 | B12: 6909.51 | C12: =B12/B11 | D12: =LN(C12) | E12: =D12-$B$37 | F12: =E12^2
A13: 10 | B13: 6878.88 | C13: =B13/B12 | D13: =LN(C13) | E13: =D13-$B$37 | F13: =E13^2
A14: 11 | B14: 6740.02 | C14: =B14/B13 | D14: =LN(C14) | E14: =D14-$B$37 | F14: =E14^2
A15: 12 | B15: 6632.19 | C15: =B15/B14 | D15: =LN(C15) | E15: =D15-$B$37 | F15: =E15^2
A16: 13 | B16: 6506.48 | C16: =B16/B15 | D16: =LN(C16) | E16: =D16-$B$37 | F16: =E16^2
... A30: 27 | B30: 7358.22 | C30: =B30/B29 | D30: =LN(C30) | E30: =D30-$B$37 | F30: =E30^2
A31: 28
A32: 29
A33: 30
E34: total | F34: total
B35: SUMMARY STATISTICS | E35: =SUM(D5:D33) | F35: =SUM(F5:F33)
A36: n(price relatives) | B36: =COUNT(C5:C33)
A37: µ̂ (log return sample mean) | B37: =SUM(D5:D33)/B36
A38: σ²_ub(unbiased variance) | B38: =SUMSQ(D5:D33)/(B36-1) - (B37^2*B36)/(B36-1)
A39: annualized variance | B39: =B38*52
A40: annual volatility σ | B40: =SQRT(B39)

Sheet T-bills
A1: T-BILL INTEREST RATE CALCULATOR
A3: B (bid discount) | B3: 3.68
A4: A (asked discount) | B4: 3.66
A5: n (calendar days to maturity) | B5: 96
A7: T-Bill price ($10,000 face value) | B7: =10000*(1-0.01*((B3+B4)/2)*(B5/360))
A8: r^-t (price / 10000) | B8: =B7/10000
A9: t (years to expiration) | B9: =B5/365
A10: r (1 + interest rate) | B10: =(B7/10000)^(-1/B9)

Sheet BS calc
A1: BLACK-SCHOLES OPTION PRICING MODEL
A3: INPUTS
A4: S (stock price) | B4: 7358.22
A5: K (striking price) | B5: 5800
A6: t (time to expiration, years) | B6: 0.263
A7: r (1 + interest rate) | B7: ='T-bills'!B10
A8: σ (volatility) | B8: ='Stock Prices'!B40
A10: INTERMEDIATE CALCULATIONS
A11: d1 | B11: =(LN(B4/B5)+(LN(B7)+0.5*B8^2)*B6)/(B8*SQRT(B6))
A12: d2 | B12: =B11-B8*SQRT(B6)
A13: N(d1) | B13: =_xlfn.NORM.S.DIST(B11,1)
A14: N(d2) | B14: =_xlfn.NORM.S.DIST(B12,1)
A16: OUTPUT
A17: Call price | B17: =B4*B13-B5*(B7^(-B6))*B14
A18: Put price | B18: =B17-B4+B5*(B7^(-B6))
A20: GREEKS
A21: Delta | B21: =_xlfn.NORM.S.DIST(B11,1)
A22: Gamma | B22: =(1/(B4*B8*SQRT(B6)))*(1/SQRT(2*PI()))*EXP(-0.5*B11^2)
A23: Theta | B23: =(-( B4*B8*(1/SQRT(2*PI()))*EXP(-0.5*B11^2))/(2*SQRT(B6))-LN(B7)*B5*(B7^(-B6))*_xlfn.NORM.S.DIST(B12,1))/365
A24: Vega | B24: =(B4*SQRT(B6)*(1/SQRT(2*PI()))*EXP(-0.5*B11^2))/100
A25: Rho | B25: =(B5*B6*(B7^(-B6))*_xlfn.NORM.S.DIST(B12,1)*LN(B7))/100

Sheet Implied vol
A1: IMPLIED VOLATILITY CALCULATOR
A3: INPUTS
A4: S (stock price) | B4: ='BS calc'!B4
A5: K (striking price) | B5: ='BS calc'!B5
A6: t (time to expiration, years) | B6: ='BS calc'!B6
A7: r (1 + interest rate) | B7: ='T-bills'!B10
A8: Market price of Call | B8: 1704.6
A10: OUTPUT
A11: Implied Volatility σ | B11: 0.29153448
B13: BS Call (with trial σ) | C13: =(B4*_xlfn.NORM.S.DIST((LN(B4/B5)+(LN(B7)+0.5*B11^2)*B6)/(B11*SQRT(B6)),1))-B5*(B7^(-B6))*_xlfn.NORM.S.DIST((LN(B4/B5)+(LN(B7)+0.5*B11^2)*B6)/(B11*SQRT(B6))-B11*SQRT(B6),1)

Sheet MONTECARLO
A1: Monte carlo simulation
A3: Parameters | F3: Parameters
A4: S(stock price) | B4: ='BS calc'!B4 | F4: S(stock price) | G4: ='BS calc'!B4
A5: K(strike price) | B5: ='BS calc'!B5 | F5: K(strike price) | G5: ='BS calc'!B5
A6: t(years) | B6: ='BS calc'!B6 | F6: t(years) | G6: ='BS calc'!B6
A7: r (1+interest rate) | B7: ='BS calc'!B7 | F7: r (1+interest rate) | G7: ='BS calc'!B7
A8: σ (volatility) | B8: ='BS calc'!B8 | F8: σ (implicit volatility) | G8: ='Implied vol'!B11
A10: results | F10: results
A11: N simulations | B11: 10000 | C11: stdev | D11: =STDEV(D18:D10017)*($B$7^(-$B$6))/SQRT(B11) | F11: N simulations | G11: 10000 | H11: stdev | I11: =STDEV(I18:I10017)*($G$7^(-$G$6))/SQRT(B11)
A12: expected value call | B12: =AVERAGE(D18:D10017)*($B$7^(-$B$6)) | C12: 95% ci | D12: =D11*1.96 | F12: expected value call | G12: =AVERAGE(I18:I10517)*($B$7^(-$B$6)) | H12: 95% ci | I12: =I11*1.96
A13: payed premia | B13: 1704.6 | F13: payed premia | G13: 1704.6
A14: edge(ev-premia) | B14: =B12-B13 | D14: =B14+D11 | F14: edge(ev-premia) | G14: =G12-G13 | I14: =G14+I11
D15: =B14-D11 | I15: =G14-I11
A16: simulations | F16: simulations
A17: # | B17: z(random) | C17: asset at date | D17: payoff call | F17: # | G17: z(random) | H17: asset at date | I17: payoff call
A18: 1 | B18: =_xlfn.NORM.S.INV(RAND()) | C18: =$B$4*EXP((LN($B$7)-0.5*$B$8^2)*$B$6+$B$8*SQRT($B$6)*B18) | D18: =MAX(C18-$B$5,0) | F18: 1 | G18: =_xlfn.NORM.S.INV(RAND()) | H18: =$B$4*EXP((LN($B$7)-0.5*$B$8^2)*$B$6+$B$8*SQRT($B$6)*G18) | I18: =MAX(H18-$B$5,0)
A19: 2 | B19: =_xlfn.NORM.S.INV(RAND()) | C19: =$B$4*EXP((LN($B$7)-0.5*$B$8^2)*$B$6+$B$8*SQRT($B$6)*B19) | D19: =MAX(C19-$B$5,0) | F19: 2 | G19: =_xlfn.NORM.S.INV(RAND()) | H19: =$B$4*EXP((LN($B$7)-0.5*$B$8^2)*$B$6+$B$8*SQRT($B$6)*G19) | I19: =MAX(H19-$B$5,0)
A20: 3 | B20: =_xlfn.NORM.S.INV(RAND()) | C20: =$B$4*EXP((LN($B$7)-0.5*$B$8^2)*$B$6+$B$8*SQRT($B$6)*B20) | D20: =MAX(C20-$B$5,0) | F20: 3 | G20: =_xlfn.NORM.S.INV(RAND()) | H20: =$B$4*EXP((LN($B$7)-0.5*$B$8^2)*$B$6+$B$8*SQRT($B$6)*G20) | I20: =MAX(H20-$B$5,0)
A21: 4 | B21: =_xlfn.NORM.S.INV(RAND()) | C21: =$B$4*EXP((LN($B$7)-0.5*$B$8^2)*$B$6+$B$8*SQRT($B$6)*B21) | D21: =MAX(C21-$B$5,0) | F21: 4 | G21: =_xlfn.NORM.S.INV(RAND()) | H21: =$B$4*EXP((LN($B$7)-0.5*$B$8^2)*$B$6+$B$8*SQRT($B$6)*G21) | I21: =MAX(H21-$B$5,0)
A22: 5 | B22: =_xlfn.NORM.S.INV(RAND()) | C22: =$B$4*EXP((LN($B$7)-0.5*$B$8^2)*$B$6+$B$8*SQRT($B$6)*B22) | D22: =MAX(C22-$B$5,0) | F22: 5 | G22: =_xlfn.NORM.S.INV(RAND()) | H22: =$B$4*EXP((LN($B$7)-0.5*$B$8^2)*$B$6+$B$8*SQRT($B$6)*G22) | I22: =MAX(H22-$B$5,0)
A23: 6 | B23: =_xlfn.NORM.S.INV(RAND()) | C23: =$B$4*EXP((LN($B$7)-0.5*$B$8^2)*$B$6+$B$8*SQRT($B$6)*B23) | D23: =MAX(C23-$B$5,0) | F23: 6 | G23: =_xlfn.NORM.S.INV(RAND()) | H23: =$B$4*EXP((LN($B$7)-0.5*$B$8^2)*$B$6+$B$8*SQRT($B$6)*G23) | I23: =MAX(H23-$B$5,0)
A24: 7 | B24: =_xlfn.NORM.S.INV(RAND()) | C24: =$B$4*EXP((LN($B$7)-0.5*$B$8^2)*$B$6+$B$8*SQRT($B$6)*B24) | D24: =MAX(C24-$B$5,0) | F24: 7 | G24: =_xlfn.NORM.S.INV(RAND()) | H24: =$B$4*EXP((LN($B$7)-0.5*$B$8^2)*$B$6+$B$8*SQRT($B$6)*G24) | I24: =MAX(H24-$B$5,0)
A25: 8 | B25: =_xlfn.NORM.S.INV(RAND()) | C25: =$B$4*EXP((LN($B$7)-0.5*$B$8^2)*$B$6+$B$8*SQRT($B$6)*B25) | D25: =MAX(C25-$B$5,0) | F25: 8 | G25: =_xlfn.NORM.S.INV(RAND()) | H25: =$B$4*EXP((LN($B$7)-0.5*$B$8^2)*$B$6+$B$8*SQRT($B$6)*G25) | I25: =MAX(H25-$B$5,0)
A26: 9 | B26: =_xlfn.NORM.S.INV(RAND()) | C26: =$B$4*EXP((LN($B$7)-0.5*$B$8^2)*$B$6+$B$8*SQRT($B$6)*B26) | D26: =MAX(C26-$B$5,0) | F26: 9 | G26: =_xlfn.NORM.S.INV(RAND()) | H26: =$B$4*EXP((LN($B$7)-0.5*$B$8^2)*$B$6+$B$8*SQRT($B$6)*G26) | I26: =MAX(H26-$B$5,0)
A27: 10 | B27: =_xlfn.NORM.S.INV(RAND()) | C27: =$B$4*EXP((LN($B$7)-0.5*$B$8^2)*$B$6+$B$8*SQRT($B$6)*B27) | D27: =MAX(C27-$B$5,0) | F27: 10 | G27: =_xlfn.NORM.S.INV(RAND()) | H27: =$B$4*EXP((LN($B$7)-0.5*$B$8^2)*$B$6+$B$8*SQRT($B$6)*G27) | I27: =MAX(H27-$B$5,0)
A28: 11 | B28: =_xlfn.NORM.S.INV(RAND()) | C28: =$B$4*EXP((LN($B$7)-0.5*$B$8^2)*$B$6+$B$8*SQRT($B$6)*B28) | D28: =MAX(C28-$B$5,0) | F28: 11 | G28: =_xlfn.NORM.S.INV(RAND()) | H28: =$B$4*EXP((LN($B$7)-0.5*$B$8^2)*$B$6+$B$8*SQRT($B$6)*G28) | I28: =MAX(H28-$B$5,0)
A29: 12 | B29: =_xlfn.NORM.S.INV(RAND()) | C29: =$B$4*EXP((LN($B$7)-0.5*$B$8^2)*$B$6+$B$8*SQRT($B$6)*B29) | D29: =MAX(C29-$B$5,0) | F29: 12 | G29: =_xlfn.NORM.S.INV(RAND()) | H29: =$B$4*EXP((LN($B$7)-0.5*$B$8^2)*$B$6+$B$8*SQRT($B$6)*G29) | I29: =MAX(H29-$B$5,0)
... A5034: 5017 | B5034: =_xlfn.NORM.S.INV(RAND()) | C5034: =$B$4*EXP((LN($B$7)-0.5*$B$8^2)*$B$6+$B$8*SQRT($B$6)*B5034) | D5034: =MAX(C5034-$B$5,0) | F5034: 5017 | G5034: =_xlfn.NORM.S.INV(RAND()) | H5034: =$B$4*EXP((LN($B$7)-0.5*$B$8^2)*$B$6+$B$8*SQRT($B$6)*G5034) | I5034: =MAX(H5034-$B$5,0)
A5035: 5018 | B5035: =-B18 | C5035: =$B$4*EXP((LN($B$7)-0.5*$B$8^2)*$B$6+$B$8*SQRT($B$6)*B5035) | D5035: =MAX(C5035-$B$5,0) | F5035: 5018 | G5035: =-G18 | H5035: =$B$4*EXP((LN($B$7)-0.5*$B$8^2)*$B$6+$B$8*SQRT($B$6)*G5035) | I5035: =MAX(H5035-$B$5,0)
A5036: 5019 | B5036: =-B19 | C5036: =$B$4*EXP((LN($B$7)-0.5*$B$8^2)*$B$6+$B$8*SQRT($B$6)*B5036) | D5036: =MAX(C5036-$B$5,0) | F5036: 5019 | G5036: =-G19 | H5036: =$B$4*EXP((LN($B$7)-0.5*$B$8^2)*$B$6+$B$8*SQRT($B$6)*G5036) | I5036: =MAX(H5036-$B$5,0)
A5037: 5020 | B5037: =-B20 | C5037: =$B$4*EXP((LN($B$7)-0.5*$B$8^2)*$B$6+$B$8*SQRT($B$6)*B5037) | D5037: =MAX(C5037-$B$5,0) | F5037: 5020 | G5037: =-G20 | H5037: =$B$4*EXP((LN($B$7)-0.5*$B$8^2)*$B$6+$B$8*SQRT($B$6)*G5037) | I5037: =MAX(H5037-$B$5,0)
A5038: 5021 | B5038: =-B21 | C5038: =$B$4*EXP((LN($B$7)-0.5*$B$8^2)*$B$6+$B$8*SQRT($B$6)*B5038) | D5038: =MAX(C5038-$B$5,0) | F5038: 5021 | G5038: =-G21 | H5038: =$B$4*EXP((LN($B$7)-0.5*$B$8^2)*$B$6+$B$8*SQRT($B$6)*G5038) | I5038: =MAX(H5038-$B$5,0)
A5039: 5022 | B5039: =-B22 | C5039: =$B$4*EXP((LN($B$7)-0.5*$B$8^2)*$B$6+$B$8*SQRT($B$6)*B5039) | D5039: =MAX(C5039-$B$5,0) | F5039: 5022 | G5039: =-G22 | H5039: =$B$4*EXP((LN($B$7)-0.5*$B$8^2)*$B$6+$B$8*SQRT($B$6)*G5039) | I5039: =MAX(H5039-$B$5,0)
A5040: 5023 | B5040: =-B23 | C5040: =$B$4*EXP((LN($B$7)-0.5*$B$8^2)*$B$6+$B$8*SQRT($B$6)*B5040) | D5040: =MAX(C5040-$B$5,0) | F5040: 5023 | G5040: =-G23 | H5040: =$B$4*EXP((LN($B$7)-0.5*$B$8^2)*$B$6+$B$8*SQRT($B$6)*G5040) | I5040: =MAX(H5040-$B$5,0)
A5041: 5024 | B5041: =-B24 | C5041: =$B$4*EXP((LN($B$7)-0.5*$B$8^2)*$B$6+$B$8*SQRT($B$6)*B5041) | D5041: =MAX(C5041-$B$5,0) | F5041: 5024 | G5041: =-G24 | H5041: =$B$4*EXP((LN($B$7)-0.5*$B$8^2)*$B$6+$B$8*SQRT($B$6)*G5041) | I5041: =MAX(H5041-$B$5,0)
A5042: 5025 | B5042: =-B25 | C5042: =$B$4*EXP((LN($B$7)-0.5*$B$8^2)*$B$6+$B$8*SQRT($B$6)*B5042) | D5042: =MAX(C5042-$B$5,0) | F5042: 5025 | G5042: =-G25 | H5042: =$B$4*EXP((LN($B$7)-0.5*$B$8^2)*$B$6+$B$8*SQRT($B$6)*G5042) | I5042: =MAX(H5042-$B$5,0)
A5043: 5026 | B5043: =-B26 | C5043: =$B$4*EXP((LN($B$7)-0.5*$B$8^2)*$B$6+$B$8*SQRT($B$6)*B5043) | D5043: =MAX(C5043-$B$5,0) | F5043: 5026 | G5043: =-G26 | H5043: =$B$4*EXP((LN($B$7)-0.5*$B$8^2)*$B$6+$B$8*SQRT($B$6)*G5043) | I5043: =MAX(H5043-$B$5,0)
A5044: 5027 | B5044: =-B27 | C5044: =$B$4*EXP((LN($B$7)-0.5*$B$8^2)*$B$6+$B$8*SQRT($B$6)*B5044) | D5044: =MAX(C5044-$B$5,0) | F5044: 5027 | G5044: =-G27 | H5044: =$B$4*EXP((LN($B$7)-0.5*$B$8^2)*$B$6+$B$8*SQRT($B$6)*G5044) | I5044: =MAX(H5044-$B$5,0)
A5045: 5028 | B5045: =-B28 | C5045: =$B$4*EXP((LN($B$7)-0.5*$B$8^2)*$B$6+$B$8*SQRT($B$6)*B5045) | D5045: =MAX(C5045-$B$5,0) | F5045: 5028 | G5045: =-G28 | H5045: =$B$4*EXP((LN($B$7)-0.5*$B$8^2)*$B$6+$B$8*SQRT($B$6)*G5045) | I5045: =MAX(H5045-$B$5,0)
A5046: 5029 | B5046: =-B29 | C5046: =$B$4*EXP((LN($B$7)-0.5*$B$8^2)*$B$6+$B$8*SQRT($B$6)*B5046) | D5046: =MAX(C5046-$B$5,0) | F5046: 5029 | G5046: =-G29 | H5046: =$B$4*EXP((LN($B$7)-0.5*$B$8^2)*$B$6+$B$8*SQRT($B$6)*G5046) | I5046: =MAX(H5046-$B$5,0)
...
